Workbook

Sheet 🔒 Terms of Use
A2: Intellectual Property Notice & Terms of Use
A3: ="FY "&FYYear&" · Baobab Consulting · Confidential"
A4: © Baobab Group of Companies (incl. Baobab CFO Pty Ltd & Baobab Consulting). No unauthorised use or reproduction without prior written permission.
B5: INTELLECTUAL PROPERTY
B6: Ownership
B7: This workbook and all of its contents — including but not limited to its structure, formulas, design, data, calculations, brand elements and methodology — are the exclusive intellectual property of the Baobab Group of Companies, including Baobab CFO Pty Ltd and Baobab Consulting (collectively ‘Baobab’).
B8: Copyright
B9: © 2026 Baobab Group of Companies. All rights reserved. No part of this workbook may be reproduced, distributed, modified, adapted, translated, publicly performed, published or sub-licensed in any form or by any means, electronic or mechanical, without prior written permission from Baobab Consulting.
B10: Unauthorised Use
B11: Any unauthorised use, reproduction, distribution or modification of this workbook or its contents constitutes an infringement of Baobab’s intellectual property rights and may result in civil and/or criminal liability under the Copyright Act 1968 (Cth) and applicable intellectual property laws.
B13: TERMS OF USE
B14: Licensed Use
B15: This workbook is provided to the named client exclusively for their personal household planning purposes. Use is limited to the client and their authorised representatives. This licence is non-transferable and non-sublicensable.
B16: Prohibited Uses
B17: You may not: (a) share or distribute this workbook to any third party; (b) use it to create competing products or services; (c) remove, alter or obscure any copyright notices, branding or IP notices; (d) reverse-engineer, decompile or extract the underlying methodology.
... B27: For permissions, licensing enquiries or to report a breach of these terms, contact Baobab Consulting. Unauthorised use will be pursued.
B30: ="Prepared by Baobab Consulting · Confidential — "&FamilyName&" Group · FY "&FYYear

Sheet ⚙ Assumptions
C1: =FamilyName&" Group — Planning Assumptions"
C2: ="FY "&FYYear&" · Baobab Consulting · Confidential"
B3: © Baobab Group of Companies (incl. Baobab CFO Pty Ltd & Baobab Consulting). No unauthorised use or reproduction without prior written permission.
B4: FAMILY & GENERAL | F4: ATO TAX BRACKETS 2025–26 (Ref)
B5: Setting | C5: Value | D5: Notes | F5: Taxable Income | G5: Rate | H5: Base Tax + Marginal
B6: Financial Year | C6: 2025-26 | D6: Change each year | F6: $0 – $18,200 | G6: 0% | H6: Nil
B7: Family Name | C7: Le | F7: $18,201 – $45,000 | G7: 16c | H7: Nil + 16c over $18,200
B8: Person 1 Name | C8: Lina | F8: $45,001 – $135,000 | G8: 30c | H8: $4,288 + 30c over $45,000
B9: Person 2 Name | C9: TBC | F9: $135,001 – $190,000 | G9: 37c | H9: $31,288 + 37c over $135,000
B10: Number of Dependents | C10: 2 | D10: For tax offset calcs | F10: $190,001+ | G10: 45c | H10: $51,638 + 45c over $190,000
B11: Trust Name | C11: Le Family Trust
B12: Trust Distribution — Person 1 | C12: 1 | D12: ="% to "&Person1 | F12: Medicare Levy | G12: 2.0% | H12: On full taxable income
B13: Trust Distribution — Person 2 | C13: 0 | D13: ="% to "&Person2 | F13: LITO (max) | G13: $700 | H13: Phases out $37,500–$66,667
F14: LMITO | G14: Nil | H14: Ceased FY2022-23
B15: RATES & ASSUMPTIONS
B16: Rate | C16: Value | D16: Notes
B17: RBA Cash Rate | C17: 4.35% | D17: As at April 2026
B18: Assumed Mortgage Rate | C18: 6.20% | D18: Investment loans
B19: Assumed Mortgage Rate (PPOR) | C19: 6.00% | D19: Principal residence
B20: Inflation Assumption | C20: 3.0% | D20: CPI for cost escalation
B21: Property Growth Rate (p.a.) | C21: 5.0% | D21: Assumed capital growth
B22: Share Market Return (p.a.) | C22: 9.0% | D22: Long-run ASX avg
B23: Super Guarantee Rate | C23: 0.12 | D23: ="FY"&FYYear&" SGC rate"
B24: Concessional Cap (FY25) | C24: $30,000 | D24: ="Per ATO FY"&FYYear
B25: Non-Concessional Cap | C25: $120,000 | D25: ="Per ATO FY"&FYYear
B26: Super Growth Rate (planning) | C26: 0.07 | D26: ="Long-run nominal return est. — adjust for fund type"
B27: Retirement Drawdown Rate | C27: 0.05 | D27: ="Annual sustainable drawdown on projected super balance"
B28: 📋 HOW TO USE — ASSUMPTIONS
B29: This is the master settings hub. Change values here and they flow automatically through the entire workbook.
B30: → Yellow cells | D30: Enter your own values (names, rates, splits)
B31: → Financial Year | D31: Update FY year each July — tax brackets and rates update automatically
B32: → Trust Distribution % | D32: ="Must add up to 100%. E.g. 50% "&Person1&" / 50% "&Person2
B33: → SGC Rate | D33: ="12% for FY "&FYYear&" — ATO confirmed SGC rate"
B34: → Negative Gearing Eligible | D34: YES = property losses deductible against all income (grandfathered properties). NO = losses quarantined to rental income only. Properties acquired after 12 May 2026 set to NO from 1 Jul 2027.
B35: → CGT Discount Eligible | D35: YES = 50% CGT discount on sale of assets held >12 months (existing properties). NO = 30% minimum tax + cost base indexation. Applies to gains accruing after 1 Jul 2027 on new acquisitions.
B36: → Green cells | D36: These are reference-only — do not edit
B37: 💡 Tip | D37: Update this tab first at the start of each financial year before touching any other tab.
B40: ="Prepared by Baobab Consulting · Commercial in Confidence — "&FamilyName&" Group · FY "&FYYear
B42: CASHFLOW & TAX SETTINGS
B43: Setting | C43: Value | D43: Notes
...

Sheet 📊 Dashboard
C1: =FamilyName&" Group — Household Planning Dashboard"
C2: ="FY "&FYYear&" · Baobab Consulting · Confidential"
B3: © Baobab Group of Companies (incl. Baobab CFO Pty Ltd & Baobab Consulting). No unauthorised use or reproduction without prior written permission.
B4: Category | C4: Weekly | D4: Monthly | E4: Annual | G4: KEY PLANNING METRICS
B5: INCOME | G5: Savings Rate | H5: =IF(E11>0,(E11-E22)/E11,0) | I5: Target: >20%
B6: Salary / Wages (net take-home) | C6: ='💰 Income Planning'!F22*12/52 | D6: ='💰 Income Planning'!F22 | E6: ='💰 Income Planning'!F22*12 | G6: Debt Service Ratio | H6: =IF(E11>0,('🏦 Debt Schedule'!H16+'🏦 Debt Schedule'!H24)*12/E11,0) | I6: Target: <30%
B7: Trust / Business Income | C7: ='💰 Income Planning'!F10*12/52 | D7: ='💰 Income Planning'!F10 | E7: ='💰 Income Planning'!F10*12 | G7: Mortgage Debt / Assets | H7: =IF('📈 A+L'!E5>0,'📈 A+L'!F5/'📈 A+L'!E5,0) | I7: LVR across all loans
B8: Consulting Income | C8: ='💰 Income Planning'!F16*12/52 | D8: ='💰 Income Planning'!F16 | E8: ='💰 Income Planning'!F16*12 | G8: Emergency Fund (months) | H8: ='🎯 Goals & Super'!F6 | I8: Target: 3–6 months
B9: Investment Returns | C9: ='💰 Income Planning'!F28*12/52 | D9: ='💰 Income Planning'!F28 | E9: ='💰 Income Planning'!F28*12 | G9: Total Net Worth | H9: ='📈 A+L'!G5 | I9: Assets less Liabilities
B10: Net Rental Income | C10: ='🏘 Rental Properties'!O11/52 | D10: ='🏘 Rental Properties'!O11/12 | E10: ='🏘 Rental Properties'!O11 | G10: ="Super Balance — "&Person1 | H10: ='🎯 Goals & Super'!C23 | I10: See Goals & Super tab
B11: TOTAL INCOME | C11: =SUM(C6:C10) | D11: =C11*52/12 | E11: =C11*52 | G11: ="Super Balance — "&Person2 | H11: ='🎯 Goals & Super'!D23 | I11: See Goals & Super tab
G12: ="Estimated Tax — "&Person1 | H12: ='🧮 Tax Estimator'!C31 | I12: ="FY"&FYYear&" estimate"
B13: EXPENDITURE | G13: ="Estimated Tax — "&Person2 | H13: ='🧮 Tax Estimator'!D31 | I13: ="FY"&FYYear&" estimate"
B14: Household Expenses | C14: ='🏠 Household Expenditure'!G109/52 | D14: ='🏠 Household Expenditure'!G109/12 | E14: ='🏠 Household Expenditure'!G109 | G14: Annual Tax Combined | H14: ='🧮 Tax Estimator'!C31+'🧮 Tax Estimator'!D31+'🧮 Tax Estimator'!E31 | I14: Total tax burden
B15: Entertainment & Social | C15: ='🏠 Household Expenditure'!N34/52 | D15: ='🏠 Household Expenditure'!N34/12 | E15: ='🏠 Household Expenditure'!N34
B16: Investment Property Costs | C16: ='🏘 Rental Properties'!O10/52 | D16: ='🏘 Rental Properties'!O10/12 | E16: ='🏘 Rental Properties'!O10
B17: Debt — Investment Loans | C17: =('🏦 Debt Schedule'!H16*12)/52 | D17: ='🏦 Debt Schedule'!H16 | E17: ='🏦 Debt Schedule'!H16*12
B18: Debt — Private Loans | C18: =('🏦 Debt Schedule'!H24*12)/52 | D18: ='🏦 Debt Schedule'!H24 | E18: ='🏦 Debt Schedule'!H24*12
B19: Capital Expenditure | C19: 0 | D19: 0 | E19: 0
B20: Discretionary (Holidays) | C20: =('📅 Monthly Cashflow'!O36)/52 | D20: =('📅 Monthly Cashflow'!O36)/12 | E20: ='📅 Monthly Cashflow'!O36
B21: Savings / Investments | C21: =('📅 Monthly Cashflow'!O51)/52 | D21: =('📅 Monthly Cashflow'!O51)/12 | E21: ='📅 Monthly Cashflow'!O51
B22: TOTAL EXPENSES | C22: =SUM(C14:C21) | D22: =C22*52/12 | E22: =C22*52
B24: CASHFLOW SURPLUS / (DEFICIT)
B25: Net Cashflow | C25: =C11-C22 | D25: =C25*52/12 | E25: =C25*52
B28: 📋 HOW TO USE — DASHBOARD
B29: This tab is read-only — all figures here flow automatically from the detail tabs.
B30: → Purpose | D30: ="Get a 30-second view of the "&FamilyName&" family’s cashflow health each meeting"
B31: → Savings Rate | D31: Target >20%. If below 10% — review household expenses first
B32: → Debt Service Ratio | D32: Target <30% of income. Above 40% = financial stress zone
B33: → Net Worth | D33: Updated from the A+L tab — fill that in to see this change
B34: → Tax Combined | D34: Flows from Tax Estimator — enter income there for live estimates
B35: 💡 Tip | D35: Show this tab to clients at the start of each review meeting as a conversation starter.
B38: ="Prepared by Baobab Consulting · Commercial in Confidence — "&FamilyName&" Group · FY "&FYYear

Sheet 💰 Income Planning
C1: =FamilyName&" Group — Income Planning"
C2: ="FY "&FYYear&" · Baobab Consulting · Confidential"
B3: © Baobab Group of Companies (incl. Baobab CFO Pty Ltd & Baobab Consulting). No unauthorised use or reproduction without prior written permission.
B4: Income Source | C4: =TrustName | D4: =Person1 | E4: =Person2 | F4: Total | H4: =TrustName | I4: =Person1 | J4: =Person2 | K4: Total
C5: Monthly | D5: Monthly | E5: Monthly | F5: Monthly | H5: Annual | I5: Annual | J5: Annual | K5: Annual
B6: Business Income — Dividends
B7: Shrunk | C7: 0 | D7: 0 | E7: 0 | F7: =SUM(C7:E7) | H7: =C7*12 | I7: =D7*12 | J7: =E7*12 | K7: =SUM(H7:J7)
B8: XXX | C8: 0 | D8: 0 | E8: 0 | F8: =SUM(C8:E8) | H8: =C8*12 | I8: =D8*12 | J8: =E8*12 | K8: =SUM(H8:J8)
B9: Other Dividends | C9: 0 | D9: 0 | E9: 0 | F9: =SUM(C9:E9) | H9: =C9*12 | I9: =D9*12 | J9: =E9*12 | K9: =SUM(H9:J9)
B10: Subtotal — Business Income — Dividends | C10: =SUM(C7:C9) | D10: =SUM(D7:D9) | E10: =SUM(E7:E9) | F10: =SUM(C10:E10) | H10: =SUM(H7:H9) | I10: =SUM(I7:I9) | J10: =SUM(J7:J9) | K10: =SUM(H10:J10)
B12: Consulting Income
B13: XXX | C13: 0 | D13: 0 | E13: 0 | F13: =SUM(C13:E13) | H13: =C13*12 | I13: =D13*12 | J13: =E13*12 | K13: =SUM(H13:J13)
B14: XXX | C14: 0 | D14: 0 | E14: 0 | F14: =SUM(C14:E14) | H14: =C14*12 | I14: =D14*12 | J14: =E14*12 | K14: =SUM(H14:J14)
B15: Other State | C15: 0 | D15: 0 | E15: 0 | F15: =SUM(C15:E15) | H15: =C15*12 | I15: =D15*12 | J15: =E15*12 | K15: =SUM(H15:J15)
B16: Subtotal — Consulting Income | C16: =SUM(C13:C15) | D16: =SUM(D13:D15) | E16: =SUM(E13:E15) | F16: =SUM(C16:E16) | H16: =SUM(H13:H15) | I16: =SUM(I13:I15) | J16: =SUM(J13:J15) | K16: =SUM(H16:J16)
B18: NET SALARY — Take-home Cash Received
B19: XXX | C19: 0 | D19: 0 | E19: 0 | F19: =SUM(C19:E19) | H19: =C19*12 | I19: =D19*12 | J19: =E19*12 | K19: =SUM(H19:J19)
B20: XXX | C20: 0 | D20: 0 | E20: 0 | F20: =SUM(C20:E20) | H20: =C20*12 | I20: =D20*12 | J20: =E20*12 | K20: =SUM(H20:J20)
B21: Other | C21: 0 | D21: 0 | E21: 0 | F21: =SUM(C21:E21) | H21: =C21*12 | I21: =D21*12 | J21: =E21*12 | K21: =SUM(H21:J21)
B22: Subtotal — Net Salary / Wages | C22: =SUM(C19:C21) | D22: =SUM(D19:D21) | E22: =SUM(E19:E21) | F22: =SUM(C22:E22) | H22: =SUM(H19:H21) | I22: =SUM(I19:I21) | J22: =SUM(J19:J21) | K22: =SUM(H22:J22)
B24: Investment Income
B25: Dividend Income (cash received) | C25: 0 | D25: 0 | E25: 0 | F25: =SUM(C25:E25) | H25: =C25*12 | I25: =D25*12 | J25: =E25*12 | K25: =SUM(H25:J25)
B26: Interest Income | C26: 0 | D26: 0 | E26: 0 | F26: =SUM(C26:E26) | H26: =C26*12 | I26: =D26*12 | J26: =E26*12 | K26: =SUM(H26:J26)
B27: Other Investment | C27: 0 | D27: 0 | E27: 0 | F27: =SUM(C27:E27) | H27: =C27*12 | I27: =D27*12 | J27: =E27*12 | K27: =SUM(H27:J27)
B28: Subtotal — Investment Income | C28: =SUM(C25:C27) | D28: =SUM(D25:D27) | E28: =SUM(E25:E27) | F28: =SUM(C28:E28) | H28: =SUM(H25:H27) | I28: =SUM(I25:I27) | J28: =SUM(J25:J27) | K28: =SUM(H28:J28)
B30: TOTAL CASH INCOME
B31: TOTAL | C31: =C10+C16+C22+C28 | D31: =D10+D16+D22+D28 | E31: =E10+E16+E22+E28 | F31: =SUM(C31:E31) | H31: =H10+H16+H22+H28 | I31: =I10+I16+I22+I28 | J31: =J10+J16+J22+J28 | K31: =SUM(H31:J31)
B34: 📋 HOW TO USE — INCOME PLANNING
B35: Record NET income received in your bank account. SALARY = take-home after tax and super deducted. Enter as MONTHLY amounts — annual figures auto-calculate on the right.
B36: → Columns C/D/E = Trust / Person 1 / Person 2 monthly NET amounts (take-home cash) | D36: ="Monthly amounts: Trust | "&Person1&" | "&Person2&" (amber cells = enter here)"
B37: → Column F | D37: Total monthly — auto-calculated from C+D+E
B38: → Columns H–K | D38: Annual equivalents — auto-calculated × 12 from monthly
B39: → Franking Credits | D39: Include grossed-up value — important for Tax Estimator accuracy
B40: → Net Salary | D40: Enter after-tax take-home pay here. Use Tax Estimator for gross income
B41: 💡 Tip | D41: Enter zero ('0') not blank for unused income sources — this prevents formula errors.
B44: ="Prepared by Baobab Consulting · Commercial in Confidence — "&FamilyName&" Group · FY "&FYYear

Sheet 🧮 Tax Estimator
C1: =FamilyName&" Group — Tax Estimator"
C2: ="FY "&FYYear&" · Baobab Consulting · Confidential"
B3: © Baobab Group of Companies (incl. Baobab CFO Pty Ltd & Baobab Consulting). No unauthorised use or reproduction without prior written permission.
B4: Description | C4: =Person1 | D4: =Person2 | E4: =TrustName | F4: Combined | G4: Notes
B5: INCOME — Enter GROSS taxable amounts | H5: Type | I5: =Person1 | J5: =Person2
B6: Gross Salary / Wages | C6: 0 | D6: 0 | E6: 0 | F6: =C6+D6+E6 | H6: SGC — Employer (12%) | I6: =C36 | J6: =D36
B7: Trust Distributions Received | C7: 0 | D7: 0 | E7: 0 | F7: =C7+D7+E7 | H7: Salary Sacrifice | I7: 0 | J7: 0
B8: Consulting / Business Income | C8: 0 | D8: 0 | E8: 0 | F8: =C8+D8+E8 | H8: Personal Contributions | I8: 0 | J8: 0
B9: Net Rental Income / (Loss) | C9: 0 | D9: 0 | E9: =IF(NegGearingEligible="YES",'🏘 Rental Properties'!O11,MAX(0,'🏘 Rental Properties'!O11)) | F9: =C9+D9+E9 | G9: Trust rental auto-links from Rental Properties sheet with gearing switch. Enter personal rental (C9/D9) manually. | H9: Concessional Total | I9: =I6+I7+I8 | J9: =J6+J7+J8
B10: Dividend Income | C10: 0 | D10: 0 | E10: 0 | F10: =C10+D10+E10 | H10: ="Concessional Cap (FY"&FYYear&")" | I10: 30000 | J10: 30000
B11: Franking Credits (auto-calculated) | C11: =C10*FrankingPct*(CorpTaxRate/(1-CorpTaxRate)) | D11: =D10*FrankingPct*(CorpTaxRate/(1-CorpTaxRate)) | E11: =E10*FrankingPct*(CorpTaxRate/(1-CorpTaxRate)) | F11: =C11+D11+E11 | H11: Remaining Cap | I11: =I10-I9 | J11: =J10-J9
B12: Other Income | C12: 0 | D12: 0 | E12: 0 | F12: =C12+D12+E12
B14: ALLOWABLE DEDUCTIONS — Enter your deductible expenses below
B15: Work-Related Expenses | C15: 0 | D15: 0 | E15: 0 | F15: =C15+D15+E15
B16: Investment Property Expenses | C16: 0 | D16: 0 | E16: 0 | F16: =C16+D16+E16
B17: Income Protection Insurance | C17: 0 | D17: 0 | E17: 0 | F17: =C17+D17+E17
B18: Other Deduction | C18: 0 | D18: 0 | E18: 0 | F18: =C18+D18+E18
B19: Total Allowable Deductions | C19: =SUM(C15:C18) | D19: =SUM(D15:D18) | E19: =SUM(E15:E18) | F19: =C19+D19+E19
B21: TAXABLE INCOME | C21: =SUM(C6:C12)-C19 | D21: =SUM(D6:D12)-D19 | E21: =SUM(E6:E12)-E19 | F21: =C21+D21+E21
B23: ="TAX CALCULATION — FY "&FYYear&" ATO Rates"
B24: Gross Income Tax | C24: =IF(C21<=18200,0,IF(C21<=45000,(C21-18200)*0.16,IF(C21<=135000,4288+(C21-45000)*0.3,IF(C21<=190000,31288+(C21-135000)*0.37,51638+(C21-190000)*0.45)))) | D24: =IF(D21<=18200,0,IF(D21<=45000,(D21-18200)*0.16,IF(D21<=135000,4288+(D21-45000)*0.3,IF(D21<=190000,31288+(D21-135000)*0.37,51638+(D21-190000)*0.45)))) | E24: =E21*0.3 | F24: =C24+D24+E24
B25: Less: LITO | C25: =-MIN(C24,IF(C21<=37500,700,IF(C21<=45000,700-(C21-37500)*0.05,IF(C21<=66667,325-(C21-45000)*0.015,0)))) | D25: =-MIN(D24,IF(D21<=37500,700,IF(D21<=45000,700-(D21-37500)*0.05,IF(D21<=66667,325-(D21-45000)*0.015,0)))) | E25: 0 | F25: =C25+D25+E25
B26: Add: Medicare Levy (2%) | C26: =IF(C21>26000,C21*0.02,0) | D26: =IF(D21>26000,D21*0.02,0) | E26: 0 | F26: =C26+D26+E26
B27: Less: Franking Credits | C27: =-C11 | D27: =-D11 | E27: =-E11 | F27: =C27+D27+E27
B28: Less: PAYG Withheld during year | C28: 0 | D28: 0 | E28: 0 | F28: =C28+D28+E28
B29: Less: Other Credits & Adjustments | C29: 0 | D29: 0 | E29: 0 | F29: =C29+D29+E29
B31: TAX BALANCE DUE / (REFUND) | C31: =MAX(0,SUM(C24:C27))-C28-C29 | D31: =MAX(0,SUM(D24:D27))-D28-D29 | E31: =MAX(0,SUM(E24:E27))-E28-E29 | F31: =MAX(0,SUM(F24:F27))-F28-F29
B33: ADDITIONAL INFORMATION
B34: Effective Tax Rate | C34: =IF(C21>0,MAX(0,SUM(C24:C27))/C21,0) | D34: =IF(D21>0,MAX(0,SUM(D24:D27))/D21,0) | E34: =IF(E21>0,MAX(0,SUM(E24:E27))/E21,0) | F34: =IF(F21>0,MAX(0,SUM(F24:F27))/F21,0)
B35: Net After-Tax Income | C35: =C21-MAX(0,SUM(C24:C27)) | D35: =D21-MAX(0,SUM(D24:D27)) | E35: =E21-MAX(0,SUM(E24:E27)) | F35: =C35+D35+E35
B36: Estimated SGC — Employer (12%) | C36: =C6*SGCRate | D36: =D6*SGCRate | E36: 0 | F36: =C36+D36+E36
B37: CGT Discount on Property Sale | C37: =IF(CGTDiscountEligible="YES","50% discount applies (pre-1 Jul 2027 gains)","30% min tax + indexation (gains from 1 Jul 2027)") | D37: =IF(CGTDiscountEligible="YES","50% discount applies (pre-1 Jul 2027 gains)","30% min tax + indexation (gains from 1 Jul 2027)") | E37: =IF(CGTDiscountEligible="YES","50% discount applies","30% min tax + indexation") | G37: Set CGT Discount Eligible switch in Assumptions. From 1 Jul 2027, new property acquisitions use 30% min tax + indexation.
B38: Rental Loss Treatment | C38: =IF(NegGearingEligible="YES","Losses deductible against all income ✓","Losses quarantined to rental income only ⚠") | D38: =IF(NegGearingEligible="YES","Losses deductible against all income ✓","Losses quarantined to rental income only ⚠") | E38: =IF(NegGearingEligible="YES","Losses deductible ✓","Losses quarantined ⚠") | G38: Set Negative Gearing Eligible in Assumptions. Properties acquired after 12 May 2026 cannot offset losses against non-rental income from 1 Jul 2027.
B40: ⚠ TRUST TAX NOTE (FY2027-28 onwards)
B42: HOW TO USE — TAX ESTIMATOR
B43: → Income section | C43: Enter GROSS amounts. Salary = what employer pays before tax & super are deducted.
B44: → Deductions | C44: Name each deduction in the amber label cell. Enter amounts in C & D.
B45: → Taxable Income | C45: Gross income minus your total allowable deductions.
B46: → PAYG Withheld | C46: Enter total tax withheld from payslips — reduces your balance due.
B47: → Balance Due/(Refund) | C47: What you owe or get back at tax time after all offsets and PAYG.
...

Sheet 🏠 Household Expenditure
C1: =FamilyName&" Group — Annual Household Budget"
C2: ="FY "&FYYear&" · Baobab Consulting · Confidential"
B3: © Baobab Group of Companies (incl. Baobab CFO Pty Ltd & Baobab Consulting). No unauthorised use or reproduction without prior written permission.
B4: Expense Category | C4: Per Week (enter here) | D4: Per Month (enter here) | E4: Per Quarter (enter here) | F4: Per Year (enter here) | G4: ANNUAL TOTAL | I4: Expense Category | J4: Per Week (enter here) | K4: Per Month (enter here) | L4: Per Quarter (enter here) | M4: Per Year (enter here) | N4: ANNUAL TOTAL
B5: GROCERIES & FOOD | I5: ENTERTAINMENT — PERSON 1
B6: Groceries / Supermarket | C6: 0 | D6: 0 | E6: 0 | F6: 0 | G6: =C6*52+D6*12+E6*4+F6 | I6: Coffees | J6: 0 | K6: 0 | L6: 0 | M6: 0 | N6: =J6*52+K6*12+L6*4+M6
B7: Fresh Produce / Deli | C7: 0 | D7: 0 | E7: 0 | F7: 0 | G7: =C7*52+D7*12+E7*4+F7 | I7: Work Lunches | J7: 0 | K7: 0 | L7: 0 | M7: 0 | N7: =J7*52+K7*12+L7*4+M7
B8: Baby / Pet Food | C8: 0 | D8: 0 | E8: 0 | F8: 0 | G8: =C8*52+D8*12+E8*4+F8 | I8: Weekend Brunches / Lunches | J8: 0 | K8: 0 | L8: 0 | M8: 0 | N8: =J8*52+K8*12+L8*4+M8
B9: Total — GROCERIES & FOOD | G9: =SUM(G6:G8) | I9: Dinners Out | J9: 0 | K9: 0 | L9: 0 | M9: 0 | N9: =J9*52+K9*12+L9*4+M9
B10: HOME — PRINCIPAL RESIDENCE | I10: Pub / Bar | J10: 0 | K10: 0 | L10: 0 | M10: 0 | N10: =J10*52+K10*12+L10*4+M10
B11: Council Rates | C11: 0 | D11: 0 | E11: 0 | F11: 0 | G11: =C11*52+D11*12+E11*4+F11 | I11: Weekends Away | J11: 0 | K11: 0 | L11: 0 | M11: 0 | N11: =J11*52+K11*12+L11*4+M11
B12: Water | C12: 0 | D12: 0 | E12: 0 | F12: 0 | G12: =C12*52+D12*12+E12*4+F12 | I12: Personal Cash | J12: 0 | K12: 0 | L12: 0 | M12: 0 | N12: =J12*52+K12*12+L12*4+M12
B13: Electricity | C13: 0 | D13: 0 | E13: 0 | F13: 0 | G13: =C13*52+D13*12+E13*4+F13 | I13: Total — ENTERTAINMENT — PERSON 1 | N13: =SUM(N6:N12)
B14: Gas | C14: 0 | D14: 0 | E14: 0 | F14: 0 | G14: =C14*52+D14*12+E14*4+F14 | I14: ENTERTAINMENT — PERSON 2
B15: Home Insurance | C15: 0 | D15: 0 | E15: 0 | F15: 0 | G15: =C15*52+D15*12+E15*4+F15 | I15: Coffees | J15: 0 | K15: 0 | L15: 0 | M15: 0 | N15: =J15*52+K15*12+L15*4+M15
B16: Contents Insurance | C16: 0 | D16: 0 | E16: 0 | F16: 0 | G16: =C16*52+D16*12+E16*4+F16 | I16: Work Lunches | J16: 0 | K16: 0 | L16: 0 | M16: 0 | N16: =J16*52+K16*12+L16*4+M16
B17: Major Household (furniture, appliances) | C17: 0 | D17: 0 | E17: 0 | F17: 0 | G17: =C17*52+D17*12+E17*4+F17 | I17: Weekend Brunches / Lunches | J17: 0 | K17: 0 | L17: 0 | M17: 0 | N17: =J17*52+K17*12+L17*4+M17
B18: Minor Maintenance & Garden | C18: 0 | D18: 0 | E18: 0 | F18: 0 | G18: =C18*52+D18*12+E18*4+F18 | I18: Dinners Out | J18: 0 | K18: 0 | L18: 0 | M18: 0 | N18: =J18*52+K18*12+L18*4+M18
B19: Total — HOME — PRINCIPAL RESIDENCE | G19: =SUM(G11:G18) | I19: Pub / Bar | J19: 0 | K19: 0 | L19: 0 | M19: 0 | N19: =J19*52+K19*12+L19*4+M19
B20: POOL & OUTDOOR | I20: Weekends Away | J20: 0 | K20: 0 | L20: 0 | M20: 0 | N20: =J20*52+K20*12+L20*4+M20
B21: Pool Maintenance | C21: 0 | D21: 0 | E21: 0 | F21: 0 | G21: =C21*52+D21*12+E21*4+F21 | I21: Personal Cash | J21: 0 | K21: 0 | L21: 0 | M21: 0 | N21: =J21*52+K21*12+L21*4+M21
B22: Gardening / Lawn | C22: 0 | D22: 0 | E22: 0 | F22: 0 | G22: =C22*52+D22*12+E22*4+F22 | I22: Total — ENTERTAINMENT — PERSON 2 | N22: =SUM(N15:N21)
B23: Total — POOL & OUTDOOR | G23: =SUM(G21:G22) | I23: ENTERTAINMENT — JOINT / FAMILY
B24: TELEPHONE & INTERNET | I24: Restaurants | J24: 0 | K24: 0 | L24: 0 | M24: 0 | N24: =J24*52+K24*12+L24*4+M24
B25: Fixed Line / NBN | C25: 0 | D25: 0 | E25: 0 | F25: 0 | G25: =C25*52+D25*12+E25*4+F25 | I25: Fast Food / Takeaway | J25: 0 | K25: 0 | L25: 0 | M25: 0 | N25: =J25*52+K25*12+L25*4+M25
B26: Mobile — Person 1 | C26: 0 | D26: 0 | E26: 0 | F26: 0 | G26: =C26*52+D26*12+E26*4+F26 | I26: Outings (cinema, sport, concerts) | J26: 0 | K26: 0 | L26: 0 | M26: 0 | N26: =J26*52+K26*12+L26*4+M26
B27: Mobile — Person 2 | C27: 0 | D27: 0 | E27: 0 | F27: 0 | G27: =C27*52+D27*12+E27*4+F27 | I27: Kids Entertainment | J27: 0 | K27: 0 | L27: 0 | M27: 0 | N27: =J27*52+K27*12+L27*4+M27
B28: Mobile — Dependents | C28: 0 | D28: 0 | E28: 0 | F28: 0 | G28: =C28*52+D28*12+E28*4+F28 | I28: Beer & Wine (home) | J28: 0 | K28: 0 | L28: 0 | M28: 0 | N28: =J28*52+K28*12+L28*4+M28
B29: Total — TELEPHONE & INTERNET | G29: =SUM(G25:G28) | I29: Home Entertaining | J29: 0 | K29: 0 | L29: 0 | M29: 0 | N29: =J29*52+K29*12+L29*4+M29
B30: STREAMING & SUBSCRIPTIONS | I30: Family Activities | J30: 0 | K30: 0 | L30: 0 | M30: 0 | N30: =J30*52+K30*12+L30*4+M30
B31: Netflix / Stan / Disney | C31: 0 | D31: 0 | E31: 0 | F31: 0 | G31: =C31*52+D31*12+E31*4+F31 | I31: Total — ENTERTAINMENT — JOINT / FAMILY | N31: =SUM(N24:N30)
B32: Spotify / Music | C32: 0 | D32: 0 | E32: 0 | F32: 0 | G32: =C32*52+D32*12+E32*4+F32
B33: News / Magazines | C33: 0 | D33: 0 | E33: 0 | F33: 0 | G33: =C33*52+D33*12+E33*4+F33 | I33: TOTAL ENTERTAINMENT SPEND
B34: Other Subscriptions | C34: 0 | D34: 0 | E34: 0 | F34: 0 | G34: =C34*52+D34*12+E34*4+F34 | I34: TOTAL ENTERTAINMENT | N34: =N13+N22+N31
B35: Total — STREAMING & SUBSCRIPTIONS | G35: =SUM(G31:G34)
B36: VEHICLE 1
B37: Insurance | C37: 0 | D37: 0 | E37: 0 | F37: 0 | G37: =C37*52+D37*12+E37*4+F37
B38: Registration | C38: 0 | D38: 0 | E38: 0 | F38: 0 | G38: =C38*52+D38*12+E38*4+F38
B39: Lease / Loan Payment | C39: 0 | D39: 0 | E39: 0 | F39: 0 | G39: =C39*52+D39*12+E39*4+F39
B40: Fuel | C40: 0 | D40: 0 | E40: 0 | F40: 0 | G40: =C40*52+D40*12+E40*4+F40
...

Sheet 📅 Monthly Cashflow
C1: =FamilyName&" Group — 12-Month Cashflow Calendar"
C2: ="FY "&FYYear&" · Baobab Consulting · Confidential"
B3: © Baobab Group of Companies (incl. Baobab CFO Pty Ltd & Baobab Consulting). No unauthorised use or reproduction without prior written permission.
B4: INCOME | C4: Jan | D4: Feb | E4: Mar | F4: Apr | G4: May | H4: Jun | I4: Jul | J4: Aug | K4: Sep | L4: Oct | M4: Nov | N4: Dec | O4: ANNUAL TOTAL
B5: ="Salary — "&Person1 | C5: ='💰 Income Planning'!D22 | D5: ='💰 Income Planning'!D22 | E5: ='💰 Income Planning'!D22 | F5: ='💰 Income Planning'!D22 | G5: ='💰 Income Planning'!D22 | H5: ='💰 Income Planning'!D22 | I5: ='💰 Income Planning'!D22 | J5: ='💰 Income Planning'!D22 | K5: ='💰 Income Planning'!D22 | L5: ='💰 Income Planning'!D22 | M5: ='💰 Income Planning'!D22 | N5: ='💰 Income Planning'!D22 | O5: ='💰 Income Planning'!D22*12
B6: ="Salary — "&Person2 | C6: ='💰 Income Planning'!E22 | D6: ='💰 Income Planning'!E22 | E6: ='💰 Income Planning'!E22 | F6: ='💰 Income Planning'!E22 | G6: ='💰 Income Planning'!E22 | H6: ='💰 Income Planning'!E22 | I6: ='💰 Income Planning'!E22 | J6: ='💰 Income Planning'!E22 | K6: ='💰 Income Planning'!E22 | L6: ='💰 Income Planning'!E22 | M6: ='💰 Income Planning'!E22 | N6: ='💰 Income Planning'!E22 | O6: ='💰 Income Planning'!E22*12
B7: Trust Distributions | C7: ='💰 Income Planning'!F10 | D7: ='💰 Income Planning'!F10 | E7: ='💰 Income Planning'!F10 | F7: ='💰 Income Planning'!F10 | G7: ='💰 Income Planning'!F10 | H7: ='💰 Income Planning'!F10 | I7: ='💰 Income Planning'!F10 | J7: ='💰 Income Planning'!F10 | K7: ='💰 Income Planning'!F10 | L7: ='💰 Income Planning'!F10 | M7: ='💰 Income Planning'!F10 | N7: ='💰 Income Planning'!F10 | O7: ='💰 Income Planning'!F10*12
B8: Consulting Income | C8: ='💰 Income Planning'!F16 | D8: ='💰 Income Planning'!F16 | E8: ='💰 Income Planning'!F16 | F8: ='💰 Income Planning'!F16 | G8: ='💰 Income Planning'!F16 | H8: ='💰 Income Planning'!F16 | I8: ='💰 Income Planning'!F16 | J8: ='💰 Income Planning'!F16 | K8: ='💰 Income Planning'!F16 | L8: ='💰 Income Planning'!F16 | M8: ='💰 Income Planning'!F16 | N8: ='💰 Income Planning'!F16 | O8: ='💰 Income Planning'!F16*12
B9: Rental Income (net) | C9: ='🏘 Rental Properties'!O11/12 | D9: ='🏘 Rental Properties'!O11/12 | E9: ='🏘 Rental Properties'!O11/12 | F9: ='🏘 Rental Properties'!O11/12 | G9: ='🏘 Rental Properties'!O11/12 | H9: ='🏘 Rental Properties'!O11/12 | I9: ='🏘 Rental Properties'!O11/12 | J9: ='🏘 Rental Properties'!O11/12 | K9: ='🏘 Rental Properties'!O11/12 | L9: ='🏘 Rental Properties'!O11/12 | M9: ='🏘 Rental Properties'!O11/12 | N9: ='🏘 Rental Properties'!O11/12 | O9: ='🏘 Rental Properties'!O11
B10: Dividends / Investment | C10: ='💰 Income Planning'!F28 | D10: ='💰 Income Planning'!F28 | E10: ='💰 Income Planning'!F28 | F10: ='💰 Income Planning'!F28 | G10: ='💰 Income Planning'!F28 | H10: ='💰 Income Planning'!F28 | I10: ='💰 Income Planning'!F28 | J10: ='💰 Income Planning'!F28 | K10: ='💰 Income Planning'!F28 | L10: ='💰 Income Planning'!F28 | M10: ='💰 Income Planning'!F28 | N10: ='💰 Income Planning'!F28 | O10: ='💰 Income Planning'!F28*12
B11: Total — INCOME | C11: =SUM(C5:C10) | D11: =SUM(D5:D10) | E11: =SUM(E5:E10) | F11: =SUM(F5:F10) | G11: =SUM(G5:G10) | H11: =SUM(H5:H10) | I11: =SUM(I5:I10) | J11: =SUM(J5:J10) | ... O11: =SUM(O5:O10)
B12: HOUSEHOLD EXPENSES
B13: Groceries & Food | C13: =IF(CashflowLink="YES",'🏠 Household Expenditure'!G9/12,0) | D13: =IF(CashflowLink="YES",'🏠 Household Expenditure'!G9/12,0) | E13: =IF(CashflowLink="YES",'🏠 Household Expenditure'!G9/12,0) | F13: =IF(CashflowLink="YES",'🏠 Household Expenditure'!G9/12,0) | G13: =IF(CashflowLink="YES",'🏠 Household Expenditure'!G9/12,0) | H13: =IF(CashflowLink="YES",'🏠 Household Expenditure'!G9/12,0) | I13: =IF(CashflowLink="YES",'🏠 Household Expenditure'!G9/12,0) | J13: =IF(CashflowLink="YES",'🏠 Household Expenditure'!G9/12,0) | K13: =IF(CashflowLink="YES",'🏠 Household Expenditure'!G9/12,0) | L13: =IF(CashflowLink="YES",'🏠 Household Expenditure'!G9/12,0) | M13: =IF(CashflowLink="YES",'🏠 Household Expenditure'!G9/12,0) | N13: =IF(CashflowLink="YES",'🏠 Household Expenditure'!G9/12,0) | O13: =SUM(C13:N13)
B14: Utilities (electricity, gas, water) | C14: =IF(CashflowLink="YES",('🏠 Household Expenditure'!G19+'🏠 Household Expenditure'!G23)/12,0) | D14: =IF(CashflowLink="YES",('🏠 Household Expenditure'!G19+'🏠 Household Expenditure'!G23)/12,0) | E14: =IF(CashflowLink="YES",('🏠 Household Expenditure'!G19+'🏠 Household Expenditure'!G23)/12,0) | F14: =IF(CashflowLink="YES",('🏠 Household Expenditure'!G19+'🏠 Household Expenditure'!G23)/12,0) | G14: =IF(CashflowLink="YES",('🏠 Household Expenditure'!G19+'🏠 Household Expenditure'!G23)/12,0) | H14: =IF(CashflowLink="YES",('🏠 Household Expenditure'!G19+'🏠 Household Expenditure'!G23)/12,0) | I14: =IF(CashflowLink="YES",('🏠 Household Expenditure'!G19+'🏠 Household Expenditure'!G23)/12,0) | J14: =IF(CashflowLink="YES",('🏠 Household Expenditure'!G19+'🏠 Household Expenditure'!G23)/12,0) | K14: =IF(CashflowLink="YES",('🏠 Household Expenditure'!G19+'🏠 Household Expenditure'!G23)/12,0) | L14: =IF(CashflowLink="YES",('🏠 Household Expenditure'!G19+'🏠 Household Expenditure'!G23)/12,0) | M14: =IF(CashflowLink="YES",('🏠 Household Expenditure'!G19+'🏠 Household Expenditure'!G23)/12,0) | N14: =IF(CashflowLink="YES",('🏠 Household Expenditure'!G19+'🏠 Household Expenditure'!G23)/12,0) | O14: =SUM(C14:N14)
B15: Council Rates (usually quarterly) | C15: =IF(CashflowLink="YES",'🏠 Household Expenditure'!G29/12,0) | D15: =IF(CashflowLink="YES",'🏠 Household Expenditure'!G29/12,0) | E15: =IF(CashflowLink="YES",'🏠 Household Expenditure'!G29/12,0) | F15: =IF(CashflowLink="YES",'🏠 Household Expenditure'!G29/12,0) | G15: =IF(CashflowLink="YES",'🏠 Household Expenditure'!G29/12,0) | H15: =IF(CashflowLink="YES",'🏠 Household Expenditure'!G29/12,0) | I15: =IF(CashflowLink="YES",'🏠 Household Expenditure'!G29/12,0) | J15: =IF(CashflowLink="YES",'🏠 Household Expenditure'!G29/12,0) | K15: =IF(CashflowLink="YES",'🏠 Household Expenditure'!G29/12,0) | L15: =IF(CashflowLink="YES",'🏠 Household Expenditure'!G29/12,0) | M15: =IF(CashflowLink="YES",'🏠 Household Expenditure'!G29/12,0) | N15: =IF(CashflowLink="YES",'🏠 Household Expenditure'!G29/12,0) | O15: =SUM(C15:N15)
B16: Insurance — Home & Car | C16: =IF(CashflowLink="YES",'🏠 Household Expenditure'!G65/12,0) | D16: =IF(CashflowLink="YES",'🏠 Household Expenditure'!G65/12,0) | E16: =IF(CashflowLink="YES",'🏠 Household Expenditure'!G65/12,0) | F16: =IF(CashflowLink="YES",'🏠 Household Expenditure'!G65/12,0) | G16: =IF(CashflowLink="YES",'🏠 Household Expenditure'!G65/12,0) | H16: =IF(CashflowLink="YES",'🏠 Household Expenditure'!G65/12,0) | I16: =IF(CashflowLink="YES",'🏠 Household Expenditure'!G65/12,0) | J16: =IF(CashflowLink="YES",'🏠 Household Expenditure'!G65/12,0) | K16: =IF(CashflowLink="YES",'🏠 Household Expenditure'!G65/12,0) | L16: =IF(CashflowLink="YES",'🏠 Household Expenditure'!G65/12,0) | M16: =IF(CashflowLink="YES",'🏠 Household Expenditure'!G65/12,0) | N16: =IF(CashflowLink="YES",'🏠 Household Expenditure'!G65/12,0) | O16: =SUM(C16:N16)
B17: Subscriptions & Streaming | C17: =IF(CashflowLink="YES",'🏠 Household Expenditure'!G35/12,0) | D17: =IF(CashflowLink="YES",'🏠 Household Expenditure'!G35/12,0) | E17: =IF(CashflowLink="YES",'🏠 Household Expenditure'!G35/12,0) | F17: =IF(CashflowLink="YES",'🏠 Household Expenditure'!G35/12,0) | G17: =IF(CashflowLink="YES",'🏠 Household Expenditure'!G35/12,0) | H17: =IF(CashflowLink="YES",'🏠 Household Expenditure'!G35/12,0) | I17: =IF(CashflowLink="YES",'🏠 Household Expenditure'!G35/12,0) | J17: =IF(CashflowLink="YES",'🏠 Household Expenditure'!G35/12,0) | K17: =IF(CashflowLink="YES",'🏠 Household Expenditure'!G35/12,0) | L17: =IF(CashflowLink="YES",'🏠 Household Expenditure'!G35/12,0) | M17: =IF(CashflowLink="YES",'🏠 Household Expenditure'!G35/12,0) | N17: =IF(CashflowLink="YES",'🏠 Household Expenditure'!G35/12,0) | O17: =SUM(C17:N17)
B18: Total — HOUSEHOLD EXPENSES | C18: =SUM(C13:C17) | D18: =SUM(D13:D17) | E18: =SUM(E13:E17) | F18: =SUM(F13:F17) | G18: =SUM(G13:G17) | H18: =SUM(H13:H17) | I18: =SUM(I13:I17) | J18: =SUM(J13:J17) | ... O18: =SUM(O13:O17)
B19: EDUCATION & CHILDREN
B20: School Fees (Term 1) | C20: =IF(CashflowLink="YES",0,0) | D20: =IF(CashflowLink="YES",'🏠 Household Expenditure'!G81*0.6/4,0) | E20: =IF(CashflowLink="YES",0,0) | F20: =IF(CashflowLink="YES",0,0) | G20: =IF(CashflowLink="YES",0,0) | H20: =IF(CashflowLink="YES",0,0) | I20: =IF(CashflowLink="YES",0,0) | J20: =IF(CashflowLink="YES",0,0) | K20: =IF(CashflowLink="YES",0,0) | L20: =IF(CashflowLink="YES",0,0) | ... N20: =IF(CashflowLink="YES",0,0) | O20: =SUM(C20:N20)
B21: School Fees (Term 2) | C21: =IF(CashflowLink="YES",0,0) | D21: =IF(CashflowLink="YES",0,0) | E21: =IF(CashflowLink="YES",0,0) | F21: =IF(CashflowLink="YES",0,0) | G21: =IF(CashflowLink="YES",'🏠 Household Expenditure'!G81*0.6/4,0) | H21: =IF(CashflowLink="YES",0,0) | I21: =IF(CashflowLink="YES",0,0) | J21: =IF(CashflowLink="YES",0,0) | K21: =IF(CashflowLink="YES",0,0) | L21: =IF(CashflowLink="YES",0,0) | M21: =IF(CashflowLink="YES",0,0) | N21: =IF(CashflowLink="YES",0,0) | O21: =SUM(C21:N21)
B22: School Fees (Term 3) | C22: =IF(CashflowLink="YES",0,0) | D22: =IF(CashflowLink="YES",0,0) | E22: =IF(CashflowLink="YES",0,0) | F22: =IF(CashflowLink="YES",0,0) | G22: =IF(CashflowLink="YES",0,0) | H22: =IF(CashflowLink="YES",0,0) | I22: =IF(CashflowLink="YES",'🏠 Household Expenditure'!G81*0.6/4,0) | J22: =IF(CashflowLink="YES",0,0) | K22: =IF(CashflowLink="YES",0,0) | L22: =IF(CashflowLink="YES",0,0) | M22: =IF(CashflowLink="YES",0,0) | N22: =IF(CashflowLink="YES",0,0) | O22: =SUM(C22:N22)
B23: School Fees (Term 4) | C23: =IF(CashflowLink="YES",0,0) | D23: =IF(CashflowLink="YES",0,0) | E23: =IF(CashflowLink="YES",0,0) | F23: =IF(CashflowLink="YES",0,0) | G23: =IF(CashflowLink="YES",0,0) | H23: =IF(CashflowLink="YES",0,0) | I23: =IF(CashflowLink="YES",0,0) | J23: =IF(CashflowLink="YES",0,0) | K23: =IF(CashflowLink="YES",0,0) | L23: =IF(CashflowLink="YES",'🏠 Household Expenditure'!G81*0.6/4,0) | M23: =IF(CashflowLink="YES",0,0) | N23: =IF(CashflowLink="YES",0,0) | O23: =SUM(C23:N23)
B24: Uniforms & Books | C24: =IF(CashflowLink="YES",'🏠 Household Expenditure'!G81*0.2/12,0) | D24: =IF(CashflowLink="YES",'🏠 Household Expenditure'!G81*0.2/12,0) | E24: =IF(CashflowLink="YES",'🏠 Household Expenditure'!G81*0.2/12,0) | F24: =IF(CashflowLink="YES",'🏠 Household Expenditure'!G81*0.2/12,0) | G24: =IF(CashflowLink="YES",'🏠 Household Expenditure'!G81*0.2/12,0) | H24: =IF(CashflowLink="YES",'🏠 Household Expenditure'!G81*0.2/12,0) | I24: =IF(CashflowLink="YES",'🏠 Household Expenditure'!G81*0.2/12,0) | J24: =IF(CashflowLink="YES",'🏠 Household Expenditure'!G81*0.2/12,0) | K24: =IF(CashflowLink="YES",'🏠 Household Expenditure'!G81*0.2/12,0) | L24: =IF(CashflowLink="YES",'🏠 Household Expenditure'!G81*0.2/12,0) | M24: =IF(CashflowLink="YES",'🏠 Household Expenditure'!G81*0.2/12,0) | N24: =IF(CashflowLink="YES",'🏠 Household Expenditure'!G81*0.2/12,0) | O24: =SUM(C24:N24)
B25: Sport & Activities | C25: =IF(CashflowLink="YES",'🏠 Household Expenditure'!G81*0.2/12,0) | D25: =IF(CashflowLink="YES",'🏠 Household Expenditure'!G81*0.2/12,0) | E25: =IF(CashflowLink="YES",'🏠 Household Expenditure'!G81*0.2/12,0) | F25: =IF(CashflowLink="YES",'🏠 Household Expenditure'!G81*0.2/12,0) | G25: =IF(CashflowLink="YES",'🏠 Household Expenditure'!G81*0.2/12,0) | H25: =IF(CashflowLink="YES",'🏠 Household Expenditure'!G81*0.2/12,0) | I25: =IF(CashflowLink="YES",'🏠 Household Expenditure'!G81*0.2/12,0) | J25: =IF(CashflowLink="YES",'🏠 Household Expenditure'!G81*0.2/12,0) | K25: =IF(CashflowLink="YES",'🏠 Household Expenditure'!G81*0.2/12,0) | L25: =IF(CashflowLink="YES",'🏠 Household Expenditure'!G81*0.2/12,0) | M25: =IF(CashflowLink="YES",'🏠 Household Expenditure'!G81*0.2/12,0) | N25: =IF(CashflowLink="YES",'🏠 Household Expenditure'!G81*0.2/12,0) | O25: =SUM(C25:N25)
B26: Total — EDUCATION & CHILDREN | C26: =SUM(C20:C25) | D26: =SUM(D20:D25) | E26: =SUM(E20:E25) | F26: =SUM(F20:F25) | G26: =SUM(G20:G25) | H26: =SUM(H20:H25) | I26: =SUM(I20:I25) | J26: =SUM(J20:J25) | ... O26: =SUM(O20:O25)
B27: IRREGULAR / ONE-OFF EXPENSES
B28: Car Registration | C28: 0 | D28: 0 | E28: 0 | F28: 0 | G28: 0 | H28: 0 | I28: 0 | J28: 0 | K28: 0 | L28: 0 | M28: 0 | N28: 0 | O28: =SUM(C28:N28)
B29: Private Health — Annual Renewal | C29: 0 | D29: 0 | E29: 0 | F29: 0 | G29: 0 | H29: 0 | I29: 0 | J29: 0 | K29: 0 | L29: 0 | M29: 0 | N29: 0 | O29: =SUM(C29:N29)
B30: Dentist / Medical (annual) | C30: 0 | D30: 0 | E30: 0 | F30: 0 | G30: 0 | H30: 0 | I30: 0 | J30: 0 | K30: 0 | L30: 0 | M30: 0 | N30: 0 | O30: =SUM(C30:N30)
B31: Holidays | C31: 0 | D31: 0 | E31: 0 | F31: 0 | G31: 0 | H31: 0 | I31: 0 | J31: 0 | K31: 0 | L31: 0 | M31: 0 | N31: 0 | O31: =SUM(C31:N31)
B32: Christmas Gifts | C32: 0 | D32: 0 | E32: 0 | F32: 0 | G32: 0 | H32: 0 | I32: 0 | J32: 0 | K32: 0 | L32: 0 | M32: 0 | N32: 0 | O32: =SUM(C32:N32)
B33: Birthdays | C33: 0 | D33: 0 | E33: 0 | F33: 0 | G33: 0 | H33: 0 | I33: 0 | J33: 0 | K33: 0 | L33: 0 | M33: 0 | N33: 0 | O33: =SUM(C33:N33)
B34: Property Maintenance (unplanned) | C34: 0 | D34: 0 | E34: 0 | F34: 0 | G34: 0 | H34: 0 | I34: 0 | J34: 0 | K34: 0 | L34: 0 | M34: 0 | N34: 0 | O34: =SUM(C34:N34)
B35: Other Large Expenses | C35: 0 | D35: 0 | E35: 0 | F35: 0 | G35: 0 | H35: 0 | I35: 0 | J35: 0 | K35: 0 | L35: 0 | M35: 0 | N35: 0 | O35: =SUM(C35:N35)
B36: Total — IRREGULAR / ONE-OFF EXPENSES | C36: =SUM(C28:C35) | D36: =SUM(D28:D35) | E36: =SUM(E28:E35) | F36: =SUM(F28:F35) | G36: =SUM(G28:G35) | H36: =SUM(H28:H35) | I36: =SUM(I28:I35) | J36: =SUM(J28:J35) | ... O36: =SUM(O28:O35)
B37: DEBT REPAYMENTS
B38: ="PPOR Mortgage — "&FamilyName&" Home" | C38: ='🏦 Debt Schedule'!H24 | D38: ='🏦 Debt Schedule'!H24 | E38: ='🏦 Debt Schedule'!H24 | F38: ='🏦 Debt Schedule'!H24 | G38: ='🏦 Debt Schedule'!H24 | H38: ='🏦 Debt Schedule'!H24 | I38: ='🏦 Debt Schedule'!H24 | J38: ='🏦 Debt Schedule'!H24 | K38: ='🏦 Debt Schedule'!H24 | L38: ='🏦 Debt Schedule'!H24 | M38: ='🏦 Debt Schedule'!H24 | N38: ='🏦 Debt Schedule'!H24 | O38: =SUM(C38:N38)
B39: Investment Loan 1 | C39: =IF('🏦 Debt Schedule'!H16>0,'🏦 Debt Schedule'!H16/3,0) | D39: =IF('🏦 Debt Schedule'!H16>0,'🏦 Debt Schedule'!H16/3,0) | E39: =IF('🏦 Debt Schedule'!H16>0,'🏦 Debt Schedule'!H16/3,0) | F39: =IF('🏦 Debt Schedule'!H16>0,'🏦 Debt Schedule'!H16/3,0) | G39: =IF('🏦 Debt Schedule'!H16>0,'🏦 Debt Schedule'!H16/3,0) | H39: =IF('🏦 Debt Schedule'!H16>0,'🏦 Debt Schedule'!H16/3,0) | I39: =IF('🏦 Debt Schedule'!H16>0,'🏦 Debt Schedule'!H16/3,0) | J39: =IF('🏦 Debt Schedule'!H16>0,'🏦 Debt Schedule'!H16/3,0) | K39: =IF('🏦 Debt Schedule'!H16>0,'🏦 Debt Schedule'!H16/3,0) | L39: =IF('🏦 Debt Schedule'!H16>0,'🏦 Debt Schedule'!H16/3,0) | M39: =IF('🏦 Debt Schedule'!H16>0,'🏦 Debt Schedule'!H16/3,0) | N39: =IF('🏦 Debt Schedule'!H16>0,'🏦 Debt Schedule'!H16/3,0) | O39: =SUM(C39:N39)
B40: Investment Loan 2 | C40: =IF('🏦 Debt Schedule'!H16>0,'🏦 Debt Schedule'!H16/3,0) | D40: =IF('🏦 Debt Schedule'!H16>0,'🏦 Debt Schedule'!H16/3,0) | E40: =IF('🏦 Debt Schedule'!H16>0,'🏦 Debt Schedule'!H16/3,0) | F40: =IF('🏦 Debt Schedule'!H16>0,'🏦 Debt Schedule'!H16/3,0) | G40: =IF('🏦 Debt Schedule'!H16>0,'🏦 Debt Schedule'!H16/3,0) | H40: =IF('🏦 Debt Schedule'!H16>0,'🏦 Debt Schedule'!H16/3,0) | I40: =IF('🏦 Debt Schedule'!H16>0,'🏦 Debt Schedule'!H16/3,0) | J40: =IF('🏦 Debt Schedule'!H16>0,'🏦 Debt Schedule'!H16/3,0) | K40: =IF('🏦 Debt Schedule'!H16>0,'🏦 Debt Schedule'!H16/3,0) | L40: =IF('🏦 Debt Schedule'!H16>0,'🏦 Debt Schedule'!H16/3,0) | M40: =IF('🏦 Debt Schedule'!H16>0,'🏦 Debt Schedule'!H16/3,0) | N40: =IF('🏦 Debt Schedule'!H16>0,'🏦 Debt Schedule'!H16/3,0) | O40: =SUM(C40:N40)
...

Sheet 🏦 Debt Schedule
C1: =FamilyName&" Group — Debt Schedule"
C2: ="FY "&FYYear&" · Baobab Consulting · Confidential"
B3: © Baobab Group of Companies (incl. Baobab CFO Pty Ltd & Baobab Consulting). No unauthorised use or reproduction without prior written permission.
B4: Property / Asset | C4: Loan Balance | D4: Interest Rate | E4: P & I or IO | F4: Monthly Interest | G4: Loan Term (yrs) | H4: Monthly Repayment | I4: Type
B5: INVESTMENT LOANS (Tax Deductible)
B6: e.g. Investment Property 1 | C6: 0 | D6: 0 | E6: P&I | F6: =IF(C6>0,D6*C6/12,0) | G6: 30 | H6: =IF(C6>0,IF(E6="P&I",PMT(D6/12,G6*12,-C6),D6*C6/12),0) | I6: Investment
B7: e.g. Investment Property 2 | C7: 0 | D7: 0 | E7: P&I | F7: =IF(C7>0,D7*C7/12,0) | G7: 30 | H7: =IF(C7>0,IF(E7="P&I",PMT(D7/12,G7*12,-C7),D7*C7/12),0) | I7: Investment
B8: e.g. Investment Property 3 | C8: 0 | D8: 0 | E8: P&I | F8: =IF(C8>0,D8*C8/12,0) | G8: 30 | H8: =IF(C8>0,IF(E8="P&I",PMT(D8/12,G8*12,-C8),D8*C8/12),0) | I8: Investment
B9: e.g. Investment Property 4 | C9: 0 | D9: 0 | E9: P&I | F9: =IF(C9>0,D9*C9/12,0) | G9: 30 | H9: =IF(C9>0,IF(E9="P&I",PMT(D9/12,G9*12,-C9),D9*C9/12),0) | I9: Investment
B10: e.g. Shares / Margin Loan | C10: 0 | D10: 0 | E10: P&I | F10: =IF(C10>0,D10*C10/12,0) | G10: 30 | H10: =IF(C10>0,IF(E10="P&I",PMT(D10/12,G10*12,-C10),D10*C10/12),0) | I10: Investment
B11: e.g. Investment Property 5 | C11: 0 | D11: 0 | E11: P&I | F11: =IF(C11>0,D11*C11/12,0) | G11: 30 | H11: =IF(C11>0,IF(E11="P&I",PMT(D11/12,G11*12,-C11),D11*C11/12),0) | I11: Investment
B12: e.g. Other Investment | C12: 0 | D12: 0 | E12: P&I | F12: =IF(C12>0,D12*C12/12,0) | G12: 30 | H12: =IF(C12>0,IF(E12="P&I",PMT(D12/12,G12*12,-C12),D12*C12/12),0) | I12: Investment
C13: 0 | D13: 0 | E13: P&I | F13: =IF(C13>0,D13*C13/12,0) | G13: 30 | H13: =IF(C13>0,IF(E13="P&I",PMT(D13/12,G13*12,-C13),D13*C13/12),0) | I13: Investment
C14: 0 | D14: 0 | E14: P&I | F14: =IF(C14>0,D14*C14/12,0) | G14: 30 | H14: =IF(C14>0,IF(E14="P&I",PMT(D14/12,G14*12,-C14),D14*C14/12),0) | I14: Investment
C15: 0 | D15: 0 | E15: P&I | F15: =IF(C15>0,D15*C15/12,0) | G15: 30 | H15: =IF(C15>0,IF(E15="P&I",PMT(D15/12,G15*12,-C15),D15*C15/12),0) | I15: Investment
B16: TOTAL INVESTMENT LOANS | C16: =SUM(C6:C15) | F16: =SUM(F6:F15) | H16: =SUM(H6:H15)
B18: PRIVATE / NON-DEDUCTIBLE LOANS
B19: e.g. Principal Residence (PPOR) | C19: 0 | D19: 0 | E19: P&I | F19: =IF(C19>0,D19*C19/12,0) | G19: 30 | H19: =IF(C19>0,IF(E19="P&I",PMT(D19/12,G19*12,-C19),D19*C19/12),0) | I19: Private
B20: e.g. Vehicle Loan | C20: 0 | D20: 0 | E20: P&I | F20: =IF(C20>0,D20*C20/12,0) | G20: 30 | H20: =IF(C20>0,IF(E20="P&I",PMT(D20/12,G20*12,-C20),D20*C20/12),0) | I20: Private
B21: e.g. Personal Loan | C21: 0 | D21: 0 | E21: P&I | F21: =IF(C21>0,D21*C21/12,0) | G21: 30 | H21: =IF(C21>0,IF(E21="P&I",PMT(D21/12,G21*12,-C21),D21*C21/12),0) | I21: Private
B22: e.g. Credit Card | C22: 0 | D22: 0 | E22: P&I | F22: =IF(C22>0,D22*C22/12,0) | G22: 30 | H22: =IF(C22>0,IF(E22="P&I",PMT(D22/12,G22*12,-C22),D22*C22/12),0) | I22: Private
C23: 0 | D23: 0 | E23: P&I | F23: =IF(C23>0,D23*C23/12,0) | G23: 30 | H23: =IF(C23>0,IF(E23="P&I",PMT(D23/12,G23*12,-C23),D23*C23/12),0) | I23: Private
B24: TOTAL PRIVATE LOANS | C24: =SUM(C19:C23) | F24: =SUM(F19:F23) | H24: =SUM(H19:H23)
B26: COMBINED DEBT SUMMARY
B27: Total Loan Balance | C27: =C16 | D27: =C24 | E27: =C16+C24
B28: Total Monthly Interest | C28: =F16 | D28: =F24 | E28: =F16+F24
B29: Total Monthly Repayment | C29: =H16 | D29: =H24 | E29: =H16+H24
B32: 📋 HOW TO USE — DEBT SCHEDULE
B33: Enter loan details. Monthly repayment calculates automatically using PMT formula.
B34: → Investment Loans section | D34: All loans where interest is tax-deductible (rental properties, investment shares)
B35: → Private Loans section | D35: Home loan (PPOR), car loans, personal loans — interest NOT deductible
B36: → Interest Rate | D36: Enter as a decimal e.g. 6.2% = enter 0.062 — or Excel format 6.20%
B37: → P&I or IO | D37: Enter 'P&I' for principal + interest, or 'IO' for interest-only loans
B38: → Monthly Repayment | D38: Auto-calculated via PMT — compare to your actual bank statement
B39: → Loan Term | D39: Enter remaining years (e.g. 25 if 5 years into a 30-year loan)
B40: 💡 Tip | D40: For interest-only loans, the repayment = interest only. Ensure 'IO' is entered in the P&I column.
B43: ="Prepared by Baobab Consulting · Commercial in Confidence — "&FamilyName&" Group · FY "&FYYear

Sheet 🏘 Rental Properties
C1: =FamilyName&" Group — Rental Property Schedules"
C2: ="FY "&FYYear&" · Baobab Consulting · Confidential"
B3: © Baobab Group of Companies (incl. Baobab CFO Pty Ltd & Baobab Consulting). No unauthorised use or reproduction without prior written permission.
B4: Property 1 | E4: Property 2 | H4: Property 3 | K4: Property 4
B5: Item | C5: Annual | E5: Item | F5: Annual | H5: Item | I5: Annual | K5: Item | L5: Annual | N5: Summary Item | O5: Total (4 props)
B6: Property Address: | E6: Property Address: | H6: Property Address: | K6: Property Address:
B7: Weeks Rented: | C7: 52 | E7: Weeks Rented: | F7: 52 | H7: Weeks Rented: | I7: 52 | K7: Weeks Rented: | L7: 52
B8: Weekly Rent: | C8: 0 | E8: Weekly Rent: | F8: 0 | H8: Weekly Rent: | I8: 0 | K8: Weekly Rent: | L8: 0 | N8: PORTFOLIO SUMMARY
B9: Ownership % | C9: 1 | E9: Ownership % | F9: 1 | H9: Ownership % | I9: 1 | K9: Ownership % | L9: 1 | N9: Total Rent Received | O9: =C11+F11+I11+L11
B10: INCOME | E10: INCOME | H10: INCOME | K10: INCOME | N10: Total Expenses | O10: =C30+F30+I30+L30
B11: Rent Received | C11: =C8*C7 | E11: Rent Received | F11: =F8*F7 | H11: Rent Received | I11: =I8*I7 | K11: Rent Received | L11: =L8*L7 | N11: Total Net (Your Share) | O11: =C32+F32+I32+L32
B12: EXPENSES | E12: EXPENSES | H12: EXPENSES | K12: EXPENSES
B13: Advertising for Tenants | C13: 0 | E13: Advertising for Tenants | F13: 0 | H13: Advertising for Tenants | I13: 0 | K13: Advertising for Tenants | L13: 0
B14: Body Corporate Fees | C14: 0 | E14: Body Corporate Fees | F14: 0 | H14: Body Corporate Fees | I14: 0 | K14: Body Corporate Fees | L14: 0
B15: Borrowing Expenses | C15: 0 | E15: Borrowing Expenses | F15: 0 | H15: Borrowing Expenses | I15: 0 | K15: Borrowing Expenses | L15: 0
B16: Cleaning | C16: 0 | E16: Cleaning | F16: 0 | H16: Cleaning | I16: 0 | K16: Cleaning | L16: 0
B17: Council Rates | C17: 0 | E17: Council Rates | F17: 0 | H17: Council Rates | I17: 0 | K17: Council Rates | L17: 0
B18: Depreciation on Plant | C18: 0 | E18: Depreciation on Plant | F18: 0 | H18: Depreciation on Plant | I18: 0 | K18: Depreciation on Plant | L18: 0
B19: Gardening / Lawn Mowing | C19: 0 | E19: Gardening / Lawn Mowing | F19: 0 | H19: Gardening / Lawn Mowing | I19: 0 | K19: Gardening / Lawn Mowing | L19: 0
B20: Insurance | C20: 0 | E20: Insurance | F20: 0 | H20: Insurance | I20: 0 | K20: Insurance | L20: 0
B21: Interest on Loan | C21: 0 | E21: Interest on Loan | F21: 0 | H21: Interest on Loan | I21: 0 | K21: Interest on Loan | L21: 0
B22: Land Tax | C22: 0 | E22: Land Tax | F22: 0 | H22: Land Tax | I22: 0 | K22: Land Tax | L22: 0
B23: Legal Fees | C23: 0 | E23: Legal Fees | F23: 0 | H23: Legal Fees | I23: 0 | K23: Legal Fees | L23: 0
B24: Pest Control | C24: 0 | E24: Pest Control | F24: 0 | H24: Pest Control | I24: 0 | K24: Pest Control | L24: 0
... B29: Sundry | C29: 0 | E29: Sundry | F29: 0 | H29: Sundry | I29: 0 | K29: Sundry | L29: 0
B30: Total Expenses | C30: =SUM(C13:C29) | E30: Total Expenses | F30: =SUM(F13:F29) | H30: Total Expenses | I30: =SUM(I13:I29) | K30: Total Expenses | L30: =SUM(L13:L29)
B31: Net Profit / (Loss) | C31: =C11-C30 | E31: Net Profit / (Loss) | F31: =F11-F30 | H31: Net Profit / (Loss) | I31: =I11-I30 | K31: Net Profit / (Loss) | L31: =L11-L30
B32: Your Share (Net) | C32: =C31*C9 | E32: Your Share (Net) | F32: =F31*F9 | H32: Your Share (Net) | I32: =I31*I9 | K32: Your Share (Net) | L32: =L31*L9
B33: ⚠ Neg. Gearing Status | C33: =IF(C31>=0,"Positively geared ✓",IF(NegGearingEligible="YES","Loss deductible ✓ (grandfathered)","Loss quarantined ⚠ (post 12 May 2026 rules)")) | E33: ⚠ Neg. Gearing Status | F33: =IF(F31>=0,"Positively geared ✓",IF(NegGearingEligible="YES","Loss deductible ✓ (grandfathered)","Loss quarantined ⚠ (post 12 May 2026 rules)")) | H33: ⚠ Neg. Gearing Status | I33: =IF(I31>=0,"Positively geared ✓",IF(NegGearingEligible="YES","Loss deductible ✓ (grandfathered)","Loss quarantined ⚠ (post 12 May 2026 rules)")) | K33: ⚠ Neg. Gearing Status | L33: =IF(L31>=0,"Positively geared ✓",IF(NegGearingEligible="YES","Loss deductible ✓ (grandfathered)","Loss quarantined ⚠ (post 12 May 2026 rules)"))
B34: Deductible Loss (tax) | C34: =IF(C31>=0,0,IF(NegGearingEligible="YES",C31*C9,0)) | E34: Deductible Loss (tax) | F34: =IF(F31>=0,0,IF(NegGearingEligible="YES",F31*F9,0)) | H34: Deductible Loss (tax) | I34: =IF(I31>=0,0,IF(NegGearingEligible="YES",I31*I9,0)) | K34: Deductible Loss (tax) | L34: =IF(L31>=0,0,IF(NegGearingEligible="YES",L31*L9,0))
B35: CGT Discount on Sale | C35: =IF(CGTDiscountEligible="YES","50% discount applies","30% min tax + indexation applies") | F35: =IF(CGTDiscountEligible="YES","50% discount applies","30% min tax + indexation applies") | I35: =IF(CGTDiscountEligible="YES","50% discount applies","30% min tax + indexation applies") | K35: CGT Discount on Sale | L35: =IF(CGTDiscountEligible="YES","50% discount applies","30% min tax + indexation applies")
B39: 📋 HOW TO USE — RENTAL PROPERTIES
B40: Enter details for up to 4 rental properties. Each column is a separate property.
B41: → Weekly Rent × Weeks | D41: Formula auto-calculates gross annual rent. Adjust weeks for vacancies.
B42: → Ownership % | D42: If jointly owned 50/50, enter 0.5. Sole owner = 1.0
B43: → Expenses | D43: Enter annual cost for each expense line. Interest on Loan feeds from Debt Schedule.
B44: → Capital Works Deduction | D44: Enter annual depreciation schedule amount (from quantity surveyor report)
B45: → NET PROFIT/LOSS | D45: If negative = negatively geared. This offsets other income at tax time.
B46: → Your Share
B47: 💡 Tip | D47: Get a depreciation schedule for each property — it can add $3,000–$8,000 in annual tax deductions.
...

Sheet 🎯 Goals & Super
C1: =FamilyName&" Group — Goals, Milestones & Superannuation"
C2: ="FY "&FYYear&" · Baobab Consulting · Confidential"
B3: © Baobab Group of Companies (incl. Baobab CFO Pty Ltd & Baobab Consulting). No unauthorised use or reproduction without prior written permission.
B4: GOAL 1 — EMERGENCY FUND
B5: Item | C5: Target | D5: Current Balance | E5: Shortfall | F5: Months Coverage
B6: Emergency Fund | C6: ='🏠 Household Expenditure'!G109/2 | D6: 0 | E6: =MAX(0,C6-D6) | F6: =IF(C6>0,D6/(C6/6),0)
B8: GOAL TRACKER — SAVINGS GOALS
B9: Goal | C9: Target Amount | D9: Current Saved | E9: Target Date | F9: Monthly Req.
B10: Annual Overseas Holiday | C10: 15000 | D10: 0 | E10: Dec-25 | F10: =IF(E10="",MAX(0,(C10-D10)/12),MAX(0,(C10-D10)/MAX(1,(YEAR(DATEVALUE("1-"&E10))-YEAR(TODAY()))*12+(MONTH(DATEVALUE("1-"&E10))-MONTH(TODAY())))))
B11: Holiday Home / Short Stays | C11: 8000 | D11: 0 | E11: Dec-25 | F11: =IF(E11="",MAX(0,(C11-D11)/12),MAX(0,(C11-D11)/MAX(1,(YEAR(DATEVALUE("1-"&E11))-YEAR(TODAY()))*12+(MONTH(DATEVALUE("1-"&E11))-MONTH(TODAY())))))
B12: Education Fund — Child 1 | C12: 50000 | D12: 0 | E12: Jan-30 | F12: =IF(E12="",MAX(0,(C12-D12)/12),MAX(0,(C12-D12)/MAX(1,(YEAR(DATEVALUE("1-"&E12))-YEAR(TODAY()))*12+(MONTH(DATEVALUE("1-"&E12))-MONTH(TODAY())))))
B13: Education Fund — Child 2 | C13: 50000 | D13: 0 | E13: Jan-32 | F13: =IF(E13="",MAX(0,(C13-D13)/12),MAX(0,(C13-D13)/MAX(1,(YEAR(DATEVALUE("1-"&E13))-YEAR(TODAY()))*12+(MONTH(DATEVALUE("1-"&E13))-MONTH(TODAY())))))
B14: Car Replacement — Vehicle 1 | C14: 40000 | D14: 0 | E14: Jun-27 | F14: =IF(E14="",MAX(0,(C14-D14)/12),MAX(0,(C14-D14)/MAX(1,(YEAR(DATEVALUE("1-"&E14))-YEAR(TODAY()))*12+(MONTH(DATEVALUE("1-"&E14))-MONTH(TODAY())))))
B15: Car Replacement — Vehicle 2 | C15: 40000 | D15: 0 | E15: Jun-28 | F15: =IF(E15="",MAX(0,(C15-D15)/12),MAX(0,(C15-D15)/MAX(1,(YEAR(DATEVALUE("1-"&E15))-YEAR(TODAY()))*12+(MONTH(DATEVALUE("1-"&E15))-MONTH(TODAY())))))
B16: Home Renovation | C16: 50000 | D16: 0 | E16: Jun-26 | F16: =IF(E16="",MAX(0,(C16-D16)/12),MAX(0,(C16-D16)/MAX(1,(YEAR(DATEVALUE("1-"&E16))-YEAR(TODAY()))*12+(MONTH(DATEVALUE("1-"&E16))-MONTH(TODAY())))))
B17: Investment Property — Next Purchase | C17: 200000 | D17: 0 | E17: Jun-28 | F17: =IF(E17="",MAX(0,(C17-D17)/12),MAX(0,(C17-D17)/MAX(1,(YEAR(DATEVALUE("1-"&E17))-YEAR(TODAY()))*12+(MONTH(DATEVALUE("1-"&E17))-MONTH(TODAY())))))
B18: Other Goal 1 | C18: 0 | D18: 0 | F18: =IF(E18="",MAX(0,(C18-D18)/12),MAX(0,(C18-D18)/MAX(1,(YEAR(DATEVALUE("1-"&E18))-YEAR(TODAY()))*12+(MONTH(DATEVALUE("1-"&E18))-MONTH(TODAY())))))
B19: Other Goal 2 | C19: 0 | D19: 0 | F19: =IF(E19="",MAX(0,(C19-D19)/12),MAX(0,(C19-D19)/MAX(1,(YEAR(DATEVALUE("1-"&E19))-YEAR(TODAY()))*12+(MONTH(DATEVALUE("1-"&E19))-MONTH(TODAY())))))
B21: SUPERANNUATION TRACKER
B22: Super Item | C22: =Person1 | D22: =Person2 | E22: Notes
B23: Current Super Balance | C23: 0 | D23: 0 | E23: Enter current balance
B24: Age | C24: 0 | D24: 0 | E24: Current age
B25: Target Retirement Age | C25: 65 | D25: 65 | E25: Typical: 60-67
B26: Years to Retirement | C26: =IF(C24>0,MAX(0,C25-C24),0) | D26: =IF(D24>0,MAX(0,D25-D24),0) | E26: Auto-calculated
B27: Annual Super Contributions (Total) | C27: ='🧮 Tax Estimator'!C36+'🧮 Tax Estimator'!I7+'🧮 Tax Estimator'!I8 | D27: ='🧮 Tax Estimator'!D36+'🧮 Tax Estimator'!J7+'🧮 Tax Estimator'!J8 | E27: SGC + voluntary
B28: Projected Super at Retirement | C28: =IF(C26>0,FV(SuperGrowthRate,C26,-C27,-C23),C23) | D28: =IF(D26>0,FV(SuperGrowthRate,D26,-D27,-D23),D23) | E28: 7% p.a. growth est.
B29: Target Super at Retirement | C29: 1500000 | D29: 1500000 | E29: ASFA comfortable single
B30: Super Shortfall | C30: =MAX(0,C29-C28) | D30: =MAX(0,D29-D28)
B32: RETIREMENT INCOME PLANNING
B33: Item | C33: =Person1 | D33: =Person2 | E33: Notes
B34: Target Annual Income in Retirement | C34: 120000 | D34: 120000 | E34: ="ASFA comfortable lifestyle FY"&FYYear
B35: Expected Annual Pension Age Pension | C35: 0 | D35: 0 | E35: If eligible (FY26: ~$30,000 pa couples)
B36: Net Annual Income from Super | C36: =C28*DrawdownRate | D36: =D28*DrawdownRate | E36: Auto calc or enter
B37: Rental Income (in retirement) | C37: 0 | D37: 0 | E37: From investment properties
B38: Annual Shortfall / Surplus | C38: =C35+C36+C37-C34 | D38: =D35+D36+D37-D34
B41: 📋 HOW TO USE — GOALS & MILESTONES
B42: Track every financial goal in one place. Monthly Required auto-calculates how much to save each month.
B43: → Emergency Fund | D43: Auto-targets 6 months of expenses from the Household Expenditure tab. Fill in Current Balance.
B44: → Savings Goals table | D44: Enter Target Amount, Current Saved, and Target Date. Monthly Required calculates automatically.
B45: → Superannuation section | D45: Enter current balance and age. Review annually at end of financial year.
...

Sheet 📋 Summary
C1: =FamilyName&" Group — Household Planning Summary"
C2: ="FY "&FYYear&" · Baobab Consulting · Confidential"
B3: © Baobab Group of Companies (incl. Baobab CFO Pty Ltd & Baobab Consulting). No unauthorised use or reproduction without prior written permission.
B4: Category | C4: Weekly | D4: Monthly | E4: Annual
B5: INCOME
B6: Salary / Wages (net take-home) | C6: ='💰 Income Planning'!F22*12/52 | D6: ='💰 Income Planning'!F22 | E6: ='💰 Income Planning'!F22*12
B7: Trust / Dividends | C7: ='💰 Income Planning'!F10*12/52 | D7: ='💰 Income Planning'!F10 | E7: ='💰 Income Planning'!F10*12
B8: Consulting | C8: ='💰 Income Planning'!F16*12/52 | D8: ='💰 Income Planning'!F16 | E8: ='💰 Income Planning'!F16*12
B9: Investment Returns | C9: ='💰 Income Planning'!F28*12/52 | D9: ='💰 Income Planning'!F28 | E9: ='💰 Income Planning'!F28*12
B10: Net Rental Income | C10: ='🏘 Rental Properties'!O11/52 | D10: ='🏘 Rental Properties'!O11/12 | E10: ='🏘 Rental Properties'!O11
B11: Total INCOME | C11: =SUM(C6:C10) | D11: =SUM(D6:D10) | E11: =SUM(E6:E10)
B13: TOTAL OUTGOINGS
B14: Household Expenses | C14: ='🏠 Household Expenditure'!G109/52 | D14: ='🏠 Household Expenditure'!G109/12 | E14: ='🏠 Household Expenditure'!G109
B15: Entertainment | C15: ='🏠 Household Expenditure'!N34/52 | D15: ='🏠 Household Expenditure'!N34/12 | E15: ='🏠 Household Expenditure'!N34
B16: Investment Property | C16: ='🏘 Rental Properties'!O10/52 | D16: ='🏘 Rental Properties'!O10/12 | E16: ='🏘 Rental Properties'!O10
B17: Investment Debt | C17: =('🏦 Debt Schedule'!H16*12)/52 | D17: ='🏦 Debt Schedule'!H16 | E17: ='🏦 Debt Schedule'!H16*12
B18: Private Debt | C18: =('🏦 Debt Schedule'!H24*12)/52 | D18: ='🏦 Debt Schedule'!H24 | E18: ='🏦 Debt Schedule'!H24*12
B19: Capital Expenditure | C19: ='📅 Monthly Cashflow'!O36/52 | D19: ='📅 Monthly Cashflow'!O36/12 | E19: ='📅 Monthly Cashflow'!O36
B20: Discretionary | C20: 0 | D20: 0 | E20: 0
B21: Savings | C21: ='📅 Monthly Cashflow'!O51/52 | D21: ='📅 Monthly Cashflow'!O51/12 | E21: ='📅 Monthly Cashflow'!O51
B22: Total Outgoings | C22: =SUM(C14:C21) | D22: =SUM(D14:D21) | E22: =SUM(E14:E21)
B24: CASHFLOW SURPLUS / (DEFICIT)
B25: NET CASHFLOW | C25: =C11-C22 | D25: =D11-D22 | E25: =E11-E22
B28: 📋 HOW TO USE — SUMMARY
B29: High-level household cashflow overview. Most figures here link automatically from the detail tabs.
B30: → Purpose | D30: Share this tab with clients as the key meeting summary — one page view
B31: → Weekly / Monthly / Annual | D31: Three views of the same figures. Weekly is most relatable for day-to-day planning.
B32: → Surplus / (Deficit) | D32: Positive = cash left over. Negative = spending exceeds income — immediate action needed.
B33: → Discretionary + Savings | D33: Yellow = enter here. These are the most flexible parts of the budget.
B34: 💡 Tip | D34: The Surplus figure should ideally be zero-based (YNAB model) — every surplus dollar allocated to a Goal.
B37: ="Prepared by Baobab Consulting · Commercial in Confidence — "&FamilyName&" Group · FY "&FYYear

Sheet 📈 A+L
C1: =FamilyName&" Group — Statement of Assets & Liabilities"
C2: ="FY "&FYYear&" · Baobab Consulting · Confidential"
B3: © Baobab Group of Companies (incl. Baobab CFO Pty Ltd & Baobab Consulting). No unauthorised use or reproduction without prior written permission.
B4: Category | C4: Description | D4: Details | E4: Assets | F4: Liabilities | G4: Net Assets | H4: Ownership Entity
B5: TOTALS | E5: =E9+E15+E20+E24+E29+E33+E37+E41 | F5: =F9+F15+F20+F24+F29+F33+F37+F41 | G5: =E5-F5
B6: PROPERTY — Personal Residence
B7: PROPERTY | C7: Main Residence | D7: Enter current market value and loan balance | E7: 0 | F7: 0 | G7: =E7-F7 | H7: Joint
B8: PROPERTY | C8: Holiday Home / Investment | E8: 0 | F8: 0 | G8: =E8-F8 | H8: Joint
B9: Subtotal | E9: =SUM(E7:E8) | F9: =SUM(F7:F8) | G9: =E9-F9
B10: PROPERTY — Investment Properties
B11: PROPERTY | C11: Investment Property 1 | D11: Enter loan balance — see Debt Schedule for detail | E11: 0 | F11: 0 | G11: =E11-F11 | H11: Joint
B12: PROPERTY | C12: Investment Property 2 | D12: Enter loan balance — see Debt Schedule for detail | E12: 0 | F12: 0 | G12: =E12-F12 | H12: Joint
B13: PROPERTY | C13: Investment Property 3 | D13: Enter loan balance — see Debt Schedule for detail | E13: 0 | F13: 0 | G13: =E13-F13 | H13: =Person1
B14: PROPERTY | C14: Investment Property 4 | D14: Enter loan balance — see Debt Schedule for detail | E14: 0 | F14: 0 | G14: =E14-F14 | H14: =Person2
B15: Subtotal | E15: =SUM(E11:E14) | F15: =SUM(F11:F14) | G15: =E15-F15
B16: CASH & SAVINGS
B17: CASH & SAVINGS | C17: Transaction Accounts | E17: 0 | F17: 0 | G17: =E17-F17 | H17: Joint
B18: CASH & SAVINGS | C18: Savings Accounts | E18: 0 | F18: 0 | G18: =E18-F18 | H18: Joint
